Workbook

Sheet Tổng hợp toàn TP
A1: TỔNG HỢP TIẾN ĐỘ BỒI THƯỜNG, GPMB TOÀN THÀNH PHỐ
A2: Kỳ báo cáo: | B2: Tháng .../20...
A4: Chỉ tiêu | B4: Giá trị | C4: Nguồn / Ghi chú
A5: Tổng số dự án đang theo dõi | B5: =COUNTA('Danh mục dự án'!B4:B103) -> 2 | C5: Đếm số dự án có tên tại Danh mục dự án
A6: Trong đó - số dự án trọng điểm | B6: =COUNTIF('Danh mục dự án'!F4:F103,"Trọng điểm") -> 2 | C6: Theo Danh mục dự án trọng điểm UBND TP ban hành
A7: Số dự án đã hoàn thành / cơ bản hoàn thành | B7: =COUNTIF('Danh mục dự án'!AA4:AA103,"Đã hoàn thành")+COUNTIF('Danh mục dự án'!AA4:AA103,"Cơ bản hoàn thành") -> 0
A8: Số dự án đang triển khai | B8: =COUNTIF('Danh mục dự án'!AA4:AA103,"Đang triển khai") -> 0
A9: Số dự án chưa triển khai | B9: =COUNTIF('Danh mục dự án'!AA4:AA103,"Chưa triển khai") -> 0
A10: Số dự án chậm tiến độ so với kế hoạch | B10: =COUNTIF('Danh mục dự án'!Z4:Z103,">0") -> 2 | C10: Đếm dự án có Chênh lệch tiến độ (cột Z) > 0 ngày
A11: Tổng diện tích phải thu hồi toàn TP (m²) | B11: =SUM('Danh mục dự án'!G4:G103) -> 970000
A12: Tổng diện tích đã thu hồi, bàn giao (m²) | B12: =SUM('Danh mục dự án'!H4:H103) -> 438000 | C12: TT44/2026/TT-BTC Mẫu số 03
A13: Tỷ lệ % diện tích hoàn thành toàn TP | B13: =IFERROR(B12/B11,"") -> 0.45154639
A14: Tổng giá trị bồi thường theo phương án duyệt (triệu đồng) | B14: =SUM('Danh mục dự án'!O4:O103) -> 4900
A15: Giá trị đã chi trả lũy kế toàn TP (triệu đồng) | B15: =SUM('Danh mục dự án'!P4:P103) -> 4580 | C15: TT44/2026/TT-BTC Mẫu số 03
A16: Tỷ lệ % giá trị bồi thường đã chi trả toàn TP | B16: =IFERROR(B15/B14,"") -> 0.93469388
A17: Tổng kế hoạch vốn bồi thường, GPMB năm toàn TP (triệu đồng) | B17: =SUM('Danh mục dự án'!U4:U103) -> 1590 | C17: Luật Đầu tư công 58/2024/QH15, NĐ 85/2025/NĐ-CP
A18: Giá trị giải ngân lũy kế toàn TP (triệu đồng) | B18: =SUM('Danh mục dự án'!V4:V103) -> 610
A19: Tỷ lệ % giải ngân vốn so với kế hoạch năm toàn TP | B19: =IFERROR(B18/B17,"") -> 0.3836478

Sheet Danh mục dự án
A1: THEO DÕI TIẾN ĐỘ BỒI THƯỜNG, HỖ TRỢ, TÁI ĐỊNH CƯ CÁC DỰ ÁN
A2: Phòng Kế hoạch - Tài chính tổng hợp, báo cáo Ban Giám đốc Sở và UBND Thành phố. Ô chữ xanh dương là ví dụ minh họa (xóa trước khi dùng); các cột tỷ lệ %/chênh lệch tiến độ đã có sẵn công thức. Xem căn cứ pháp lý của từng cột tại Sheet 'Chú thích - Căn cứ pháp lý'.
A3: STT | B3: Tên dự án | C3: Dự án thành phần (nếu có) | D3: Chủ đầu tư / Đơn vị GPMB | E3: Địa bàn (Phường/Xã) | F3: Nhóm dự án | G3: Tổng diện tích phải thu hồi (m²) | H3: Diện tích đã thu hồi, bàn giao (m²) | I3: Tỷ lệ % hoàn thành diện tích | J3: Tổng số hộ/tổ chức thuộc diện thu hồi đất | K3: Số đã có TB thu hồi đất | L3: Số đã kiểm đếm | M3: Số đã có phương án bồi thường được duyệt | N3: Số đã công khai PA | O3: Số đã nhận tiền bồi thường | P3: Số đã bàn giao mặt bằng | Q3: Tổng giá trị bồi thường, hỗ trợ theo phương án duyệt (triệu đồng) | R3: Giá trị đã chi trả lũy kế (triệu đồng) | S3: Tỷ lệ % giá trị đã chi trả | T3: Số hộ thuộc diện tái định cư | U3: Số đã bố trí nền/căn hộ TĐC | V3: Số còn lại chưa bố trí TĐC | W3: Kế hoạch vốn bồi thường, GPMB năm (triệu đồng) | X3: Giá trị giải ngân lũy kế trong năm (triệu đồng) | Y3: Tỷ lệ % giải ngân vốn so với KH năm | Z3: Mốc hoàn thành GPMB theo kế hoạch | AA3: Ngày hoàn thành thực tế/dự kiến | AB3: Chênh lệch tiến độ (ngày) | AC3: Tình trạng tổng thể | AD3: Kỳ báo cáo | AE3: Ghi chú
A4: 1 | B4: DATP 1-5 Bồi thường, TĐC và xây dựng đường gom - đường Vành đai 4 TP.HCM | C4: DATP 1-5 | D4: Ban Bồi thường, GPMB TP.HCM | E4: Củ Chi | F4: Trọng điểm | G4: 850000 | H4: 320000 | I4: =IFERROR(H4/G4,"") -> 0.37647059 | J4: 4200 | K4: 4000 | L4: 3900 | M4: 3600 | N4: 3400 | O4: 3100 | P4: 2800 | Q4: 4500000 | R4: 1750000 | S4: =IFERROR(R4/Q4,"") -> 0.38888889 | T4: 1500 | U4: 900 | V4: 600 | W4: 2000000 | X4: 950000 | Y4: =IFERROR(X4/W4,"") -> 0.475 | Z4: 46752 | AA4: 46843 | AB4: =IFERROR(AA4-Z4,"") -> 91 | AC4: Đang triển khai | AD4: 09/2026 | AE4: Ví dụ minh họa - xóa trước khi nhập số liệu thật
A5: 2 | B5: Cải tạo rạch Xuyên Tâm | D5: Ban Bồi thường, GPMB TP.HCM | E5: Bình Thạnh | F5: Trọng điểm | G5: 120000 | H5: 118000 | I5: =IFERROR(H5/G5,"") -> 0.98333333 | J5: 1850 | K5: 1850 | L5: 1850 | M5: 1820 | N5: 1810 | O5: 1800 | P5: 1780 | Q5: 980000 | R5: 940000 | S5: =IFERROR(R5/Q5,"") -> 0.95918367 | T5: 700 | U5: 690 | V5: 10 | W5: 500000 | X5: 470000 | Y5: =IFERROR(X5/W5,"") -> 0.94 | Z5: 46203 | AA5: 46254 | AB5: =IFERROR(AA5-Z5,"") -> 51 | AC5: Cơ bản hoàn thành | AD5: 09/2026 | AE5: Ví dụ minh họa - xóa trước khi nhập số liệu thật
A6: 3 | I6: =IFERROR(H6/G6,"") | S6: =IFERROR(R6/Q6,"") | Y6: =IFERROR(X6/W6,"") | AB6: =IFERROR(AA6-Z6,"") -> 0
A7: 4 | I7: =IFERROR(H7/G7,"") | S7: =IFERROR(R7/Q7,"") | Y7: =IFERROR(X7/W7,"") | AB7: =IFERROR(AA7-Z7,"") -> 0
A8: 5 | I8: =IFERROR(H8/G8,"") | S8: =IFERROR(R8/Q8,"") | Y8: =IFERROR(X8/W8,"") | AB8: =IFERROR(AA8-Z8,"") -> 0
A9: 6 | I9: =IFERROR(H9/G9,"") | S9: =IFERROR(R9/Q9,"") | Y9: =IFERROR(X9/W9,"") | AB9: =IFERROR(AA9-Z9,"") -> 0
A10: 7 | I10: =IFERROR(H10/G10,"") | S10: =IFERROR(R10/Q10,"") | Y10: =IFERROR(X10/W10,"") | AB10: =IFERROR(AA10-Z10,"") -> 0
A11: 8 | I11: =IFERROR(H11/G11,"") | S11: =IFERROR(R11/Q11,"") | Y11: =IFERROR(X11/W11,"") | AB11: =IFERROR(AA11-Z11,"") -> 0
A12: 9 | I12: =IFERROR(H12/G12,"") | S12: =IFERROR(R12/Q12,"") | Y12: =IFERROR(X12/W12,"") | AB12: =IFERROR(AA12-Z12,"") -> 0
A13: 10 | I13: =IFERROR(H13/G13,"") | S13: =IFERROR(R13/Q13,"") | Y13: =IFERROR(X13/W13,"") | AB13: =IFERROR(AA13-Z13,"") -> 0
A14: 11 | I14: =IFERROR(H14/G14,"") | S14: =IFERROR(R14/Q14,"") | Y14: =IFERROR(X14/W14,"") | AB14: =IFERROR(AA14-Z14,"") -> 0
A15: 12 | I15: =IFERROR(H15/G15,"") | S15: =IFERROR(R15/Q15,"") | Y15: =IFERROR(X15/W15,"") | AB15: =IFERROR(AA15-Z15,"") -> 0
A16: 13 | I16: =IFERROR(H16/G16,"") | S16: =IFERROR(R16/Q16,"") | Y16: =IFERROR(X16/W16,"") | AB16: =IFERROR(AA16-Z16,"") -> 0
A17: 14 | I17: =IFERROR(H17/G17,"") | S17: =IFERROR(R17/Q17,"") | Y17: =IFERROR(X17/W17,"") | AB17: =IFERROR(AA17-Z17,"") -> 0
... A103: 100 | I103: =IFERROR(H103/G103,"") | S103: =IFERROR(R103/Q103,"") | Y103: =IFERROR(X103/W103,"") | AB103: =IFERROR(AA103-Z103,"") -> 0

Sheet Khó khăn - Kiến nghị
A1: TỔNG HỢP KHÓ KHĂN, VƯỚNG MẮC VÀ KIẾN NGHỊ
A2: Căn cứ: Thông tư 44/2026/TT-BTC, Mẫu số 03 (mục Khó khăn, vướng mắc; Kiến nghị). Xem chi tiết tại Sheet 'Chú thích - Căn cứ pháp lý' (mục 16).
A4: STT | B4: Tên dự án | C4: Số văn bản/ báo cáo nguồn | D4: Loại vướng mắc | E4: Nội dung vướng mắc, khó khăn | F4: Đơn vị chịu trách nhiệm xử lý | G4: Đề xuất, kiến nghị | H4: Cấp thẩm quyền xử lý | I4: Trạng thái | J4: Kỳ báo cáo | K4: Ghi chú
A5: 1
A6: 2
A7: 3
A8: 4
A9: 5
A10: 6
A11: 7
A12: 8
A13: 9
A14: 10
A15: 11
A16: 12
... A63: 59

Sheet Chú thích - Căn cứ pháp lý
A1: CHÚ THÍCH - CĂN CỨ PHÁP LÝ CỦA TỪNG CHỈ TIÊU / THÔNG TIN
A2: Lưu ý: một số chỉ tiêu được nêu đích danh trong mẫu báo cáo tại Thông tư 44/2026/TT-BTC; một số chỉ tiêu khác (kiểm đếm, phương án duyệt, bố trí tái định cư...) là mốc theo dõi nội bộ cụ thể hóa các bước trong trình tự, thủ tục bồi thường quy định tại Nghị định 88/2024/NĐ-CP, không phải chỉ tiêu bắt buộc nêu tên riêng trong mẫu biểu.
A4: STT | B4: Sheet / Cột | C4: Chỉ tiêu, thông tin | D4: Ý nghĩa - cách tính | E4: Căn cứ pháp lý
A5: 1 | B5: Danh mục dự án - Cột G | C5: Tổng diện tích phải thu hồi (m²) | D5: Diện tích đất phải thu hồi theo phương án bồi thường, hỗ trợ, TĐC đã được cấp thẩm quyền phê duyệt. | E5: Nêu tại Quyết định phê duyệt dự án/dự án thành phần bồi thường, GPMB (ví dụ Điều 1 Quyết định phê duyệt DATP).
A6: 2 | B6: Danh mục dự án - Cột H | C6: Diện tích đã thu hồi, bàn giao (m²) | D6: Khối lượng thực hiện công tác thu hồi đất đến kỳ báo cáo. | E6: Thông tư 44/2026/TT-BTC (Bộ Tài chính), Mẫu số 03, mục II.1.2: "Tổng diện tích đất được thu hồi và bàn giao đến thời điểm báo cáo".
A7: 3 | B7: Danh mục dự án - Cột I | C7: Tỷ lệ % hoàn thành diện tích | D7: Công thức = H/G. Chỉ số tính toán nội bộ, phản ánh trực tiếp 2 chỉ tiêu tại TT44/2026. | E7: Không phải chỉ tiêu bắt buộc riêng - suy ra từ 2 chỉ tiêu tại TT44/2026 Mẫu 03.
A8: 4 | B8: Danh mục dự án - Cột J, K-P | C8: Tổng số hộ/tổ chức thuộc diện thu hồi đất (J); số đã có TB thu hồi đất (K); số đã kiểm đếm (L); số đã có phương án bồi thường được duyệt (M); số đã công khai phương án bồi thường (N); số đã nhận tiền bồi thường (O); số đã bàn giao mặt bằng (P) | D8: Theo dõi tiến độ theo từng bước của trình tự bồi thường: thông báo thu hồi đất → kiểm đếm → lập/thẩm định/phê duyệt phương án → công khai phương án → chi trả → bàn giao mặt bằng. | E8: Nghị định 88/2024/NĐ-CP quy định về bồi thường, hỗ trợ, tái định cư khi Nhà nước thu hồi đất (trình tự, thủ tục thực hiện). Đây là các mốc theo dõi nội bộ cụ thể hóa quy trình tại Nghị định này. (Cột K, N bổ sung ngày cập nhật để khớp với báo cáo định kỳ thực tế của đơn vị GPMB.)
A9: 5 | B9: Danh mục dự án - Cột Q | C9: Tổng giá trị bồi thường, hỗ trợ theo phương án duyệt (triệu đồng) | D9: Giá trị theo phương án bồi thường, hỗ trợ, TĐC được cấp thẩm quyền phê duyệt. | E9: Thông tư 44/2026/TT-BTC, Mẫu số 03, mục II.1.2 (dùng làm mẫu số tính tỷ lệ giải ngân bồi thường).
A10: 6 | B10: Danh mục dự án - Cột R | C10: Giá trị đã chi trả lũy kế (triệu đồng) | D10: Giá trị đã chi trả bồi thường đến kỳ báo cáo. | E10: Thông tư 44/2026/TT-BTC, Mẫu số 03, mục II.1.2: "Giá trị bồi thường đến thời điểm báo cáo so với tổng giá trị bồi thường theo phương án bồi thường, hỗ trợ, tái định cư".
A11: 7 | B11: Danh mục dự án - Cột S | C11: Tỷ lệ % giá trị đã chi trả | D11: Công thức = R/Q. Trực tiếp phản ánh chỉ tiêu nêu tại TT44/2026 Mẫu 03. | E11: Thông tư 44/2026/TT-BTC, Mẫu số 03, mục II.1.2.
A12: 8 | B12: Danh mục dự án - Cột T-V | C12: Số hộ thuộc diện TĐC; số đã bố trí; số còn lại chưa bố trí | D12: Theo dõi công tác bố trí nền đất/căn hộ tái định cư cho hộ dân bị ảnh hưởng. | E12: Nghị định 88/2024/NĐ-CP (quy định về tái định cư khi Nhà nước thu hồi đất).
A13: 9 | B13: Danh mục dự án - Cột W | C13: Kế hoạch vốn bồi thường, GPMB năm (triệu đồng) | D13: Kế hoạch vốn đầu tư công được giao trong năm cho hạng mục bồi thường, GPMB của dự án. | E13: Luật Đầu tư công số 58/2024/QH15; Nghị định 85/2025/NĐ-CP quy định chi tiết thi hành Luật Đầu tư công (lập, giao, theo dõi kế hoạch đầu tư công).
A14: 10 | B14: Danh mục dự án - Cột X | C14: Giá trị giải ngân lũy kế trong năm (triệu đồng) | D14: Giá trị đã giải ngân từ kế hoạch vốn nêu trên, cập nhật định kỳ. | E14: Luật Đầu tư công 58/2024/QH15, NĐ 85/2025/NĐ-CP; đồng thời là số liệu cập nhật định kỳ hằng tháng theo Điều 5 Thông tư 44/2026/TT-BTC.
A15: 11 | B15: Danh mục dự án - Cột Y | C15: Tỷ lệ % giải ngân vốn so với KH năm | D15: Công thức = X/W. | E15: Suy ra từ 2 chỉ tiêu tại mục U, V nêu trên.
A16: 12 | B16: Danh mục dự án - Cột Z | C16: Mốc hoàn thành GPMB theo kế hoạch | D16: Thời hạn hoàn thành công tác bồi thường, GPMB theo tiến độ được duyệt. | E16: Nêu tại Quyết định phê duyệt dự án/dự án thành phần (mục tiến độ thực hiện).
... A22: 18 | B22: Danh mục dự án - Cột AC (gợi ý quy ước phân loại) | C22: Ngưỡng tham khảo để phân loại thống nhất | D22: Gợi ý: Tỷ lệ lũy kế các bước ≥95% và không còn vướng mắc pháp lý treo → "Cơ bản hoàn thành"/"Đã hoàn thành"; đang có vướng mắc chờ tòa án/cấp thẩm quyền xử lý hoặc chưa đủ hồ sơ pháp lý → xếp "Đang triển khai" kèm ghi chú vướng mắc; chưa phát sinh số liệu thực hiện → "Chưa triển khai". | E22: Quy ước nội bộ của KHTC để thống nhất cách đánh giá giữa các dự án - không phải chỉ tiêu bắt buộc theo TT44/2026.

Sheet DanhSachDonVi
A1: STT | B1: Tên Ban BTGPMB | C1: Tên tài khoản (Slug) | D1: Vai trò | E1: Ghi chú
A2: 1 | B2: Phòng Kế hoạch - Tài chính Sở | C2: KHTC.SNNMT | D2: Quản lý hệ thống
A3: 2 | B3: Phòng Bồi thường, hỗ trợ, tái định cư Sở | C3: BTTDC.SNNMT | D3: Quản lý nhập liệu
A4: 3 | B4: BQL DA ĐTXD các công trình giao thông thành phố (trước đây là Ban Quản lý dự án đầu tư xây dựng các công trình giao thông ) | C4: BQLDA.GiaoThong.HCM | D4: Nhập liệu | E4: Khu vực Thành phố Hồ Chí Minh cũ
A5: 4 | B5: Ban Quản lý khu công nghệ cao | C5: BQLDA.KhuCongNgheCao | D5: Nhập liệu | E5: Khu vực Thành phố Hồ Chí Minh cũ
A6: 5 | B6: Ban Quản lý Công viên Lịch sử Văn hóa-Dân tộc TPHCM | C6: BQLDA.CongVienLichSu | D6: Nhập liệu | E6: Khu vực Thành phố Hồ Chí Minh cũ
A7: 6 | B7: Ban Quản lý Đường sắt đô thị | C7: BQLDA.DuongSatDoThi | D7: Nhập liệu | E7: Khu vực Thành phố Hồ Chí Minh cũ
A8: 7 | B8: Ban QLDA ĐTXD phường Vườn Lài | C8: BQLDA.VuonLai | D8: Nhập liệu | E8: Khu vực Thành phố Hồ Chí Minh cũ
A9: 8 | B9: Ban QLDA ĐTXD phường Bình Thới | C9: BQLDA.BinhThoi | D9: Nhập liệu | E9: Khu vực Thành phố Hồ Chí Minh cũ
A10: 9 | B10: Ban QLDA ĐTXD phường Đông Hưng Thuận | C10: BQLDA.DongHungThuan | D10: Nhập liệu | E10: Khu vực Thành phố Hồ Chí Minh cũ
A11: 10 | B11: Ban QLDA phường Hạnh Thông | C11: BQLDA.HanhThong | D11: Nhập liệu | E11: Khu vực Thành phố Hồ Chí Minh cũ
A12: 11 | B12: Ban QLDA xã Vĩnh Lộc | C12: BQLDA.VinhLoc | D12: Nhập liệu | E12: Khu vực Thành phố Hồ Chí Minh cũ
A13: 12 | B13: Ban QLDA xã Tân Vĩnh Lộc | C13: BQLDA.TanVinhLoc | D13: Nhập liệu | E13: Khu vực Thành phố Hồ Chí Minh cũ
A14: 13 | B14: Ban QLDA ĐTXD phường Cát Lái | C14: BQLDA.CatLai | D14: Nhập liệu | E14: Khu vực Thành phố Hồ Chí Minh cũ
A15: 14 | B15: Ban QLDA ĐTXD phường Bình Tân | C15: BQLDA.BinhTan | D15: Nhập liệu | E15: Khu vực Thành phố Hồ Chí Minh cũ
... A50: 49 | B50: UBND phường Long Nguyên | C50: UBND.LongNguyen | D50: Nhập liệu | E50: Khu vực Bình Dương cũ

Sheet DanhSachDuAn
A1: STT | B1: Tên dự án | C1: Dựa án thành phần | D1: Ban BTGPMB | E1: Loại | F1: Khu vực
A2: 1 | B2: Dự án đầu tư xây dựng đường cao tốc TP. Hồ Chí Minh -Mộc Bài giai đoạn 1: Dự án TP3 - Bồi thường, hỗ trợ, tái định cư cao tốc TP. Hồ Chí Minh - Mộc Bài đoạn qua TP. Hồ Chí Minh | D2: BQL DA ĐTXD các công trình giao thông thành phố (trước đây là Ban Quản lý dự án đầu tư xây dựng các công trình giao thông ) | E2: Dự án trọng điểm | F2: Khu vực Thành phố Hồ Chí Minh cũ
A3: 2 | B3: Dự án cải tạo, nâng cấp Quốc lộ 22 (từ An Sương đến đường Vành đai 3) - theo hình thức hợp đồng BOT | C3: DATP1: Bồi thường, hỗ trợ, tái định cư và di dời hạ tầng phục vụ dự án Cải tạo, nâng cấp Quốc lộ 22 trên địa bàn huyện Hóc Môn thuộc dự án Cải tạo, nâng cấp Quốc lộ 22 (từ nút giao An Sương đến đường Vành đai 3) | D3: BQL DA ĐTXD các công trình giao thông thành phố (trước đây là Ban Quản lý dự án đầu tư xây dựng các công trình giao thông ) | E3: Dự án trọng điểm | F3: Khu vực Thành phố Hồ Chí Minh cũ
B4: Dự án cải tạo, nâng cấp Quốc lộ 22 (từ An Sương đến đường Vành đai 3) - theo hình thức hợp đồng BOT | C4: Dự án thành phần 2: Di dời hạ tầng phục vụ dự án cải tạo, nâng cấp Quốc lộ 22 trên địa bàn Quận 12 | E4: Dự án
A5: 3 | B5: Dự án nâng cấp, mở rộng Quốc lộ 1 (từ đường Kinh Dương Vương đến ranh tỉnh Long An) | C5: Dự án thành phần 1: Bồi thường, hỗ trợ, tái định cư trên địa bàn quận Bình Tân (nay là Phường An Lạc và Phường Tân Tạo) thuộc dự án Nâng cấp, mở rộng Quốc lộ 1 (từ đường Kinh Dương Vương đến ranh tỉnh Long An) theo phương thức đối tác công tư (Hợp đồng BOT) (nay là đường Lê Khả Phiêu) | D5: BQL DA ĐTXD các công trình giao thông thành phố (trước đây là Ban Quản lý dự án đầu tư xây dựng các công trình giao thông ) | E5: Dự án trọng điểm | F5: Khu vực Thành phố Hồ Chí Minh cũ; Dự án nâng cấp, mở rộng Quốc lộ 1 (từ đường Kinh Dương Vương đến ranh tỉnh Long An) - DA Thành phần 1
A6: 4 | B6: Dự án nâng cấp, mở rộng Quốc lộ 1 (từ đường Kinh Dương Vương đến ranh tỉnh Long An) | C6: Dự án thành phần 2: Bồi thường, hỗ trợ, tái định cư huyện Bình Chánh (nay là xã Tân Nhựt, phường Bình Chánh, phường Bình Đông,) thuộc dự án Nâng cấp mở rộng Quốc lộ 1 (từ đường Kinh Dương Vương đến ranh tỉnh Long An) theo phương thức đối tác công tư (hợp đồng BOT ) nay là đường Lê Khả Phiêu) | D6: BQL DA ĐTXD các công trình giao thông thành phố (trước đây là Ban Quản lý dự án đầu tư xây dựng các công trình giao thông ) | E6: Dự án trọng điểm | F6: Khu vực Thành phố Hồ Chí Minh cũ; Dự án nâng cấp, mở rộng Quốc lộ 1 (từ đường Kinh Dương Vương đến ranh tỉnh Long An) - DA Thành phần 2
A7: 5 | B7: Xây dựng kè chống sạt lở bờ phải sông Cần Giuộc (từ cầu Ông Thìn về thượng lưu) | D7: BQL DA ĐTXD các công trình giao thông thành phố (trước đây là Ban Quản lý dự án đầu tư xây dựng các công trình giao thông ) | E7: Dự án | F7: Khu vực Thành phố Hồ Chí Minh cũ
A8: 6 | B8: Xây dựng kè chống sạt lở bờ trái sông Sài Gòn khu vực phường Thảo Điền, quận 2 | D8: BQL DA ĐTXD các công trình giao thông thành phố (trước đây là Ban Quản lý dự án đầu tư xây dựng các công trình giao thông ) | E8: Dự án | F8: Khu vực Thành phố Hồ Chí Minh cũ
A9: 7 | B9: Mở rộng, nâng cấp đường HL80B (đoạn từ Nguyễn Ảnh Thủ đến Lê Văn Khương) | D9: BQL DA ĐTXD các công trình giao thông thành phố (trước đây là Ban Quản lý dự án đầu tư xây dựng các công trình giao thông ) | E9: Dự án | F9: Khu vực Thành phố Hồ Chí Minh cũ
A10: 8 | B10: Chống xói lở bờ sông khu vực cầu Long Kiểng | D10: BQL DA ĐTXD các công trình giao thông thành phố (trước đây là Ban Quản lý dự án đầu tư xây dựng các công trình giao thông ) | E10: Dự án | F10: Khu vực Thành phố Hồ Chí Minh cũ
A11: 9 | B11: Xây dựng cầu Kênh Ngang số 2 (đường Hoài Thanh – Lưu Hữu Phước), Phường Phú Định | D11: BQL DA ĐTXD các công trình giao thông thành phố (trước đây là Ban Quản lý dự án đầu tư xây dựng các công trình giao thông ) | E11: Dự án | F11: Khu vực Thành phố Hồ Chí Minh cũ
A12: 10 | B12: Xây dựng cầu Kênh Ngang số 3 (đường Lưu Hữu Phước), quận 8 | D12: BQL DA ĐTXD các công trình giao thông thành phố (trước đây là Ban Quản lý dự án đầu tư xây dựng các công trình giao thông ) | E12: Dự án | F12: Khu vực Thành phố Hồ Chí Minh cũ
A13: 11 | B13: Nâng cấp, mở rộng đường Nguyễn Duy Trinh (đoạn từ vành đai 2 đến đường vào Khu công nghiệp Phú Hữu) | D13: BQL DA ĐTXD các công trình giao thông thành phố (trước đây là Ban Quản lý dự án đầu tư xây dựng các công trình giao thông ) | E13: Dự án | F13: Khu vực Thành phố Hồ Chí Minh cũ
A14: 12 | B14: Xây dựng đường Liên phường Thới An - Thạnh Xuân (tuyến 2) | D14: BQL DA ĐTXD các công trình giao thông thành phố (trước đây là Ban Quản lý dự án đầu tư xây dựng các công trình giao thông ) | E14: Dự án | F14: Khu vực Thành phố Hồ Chí Minh cũ
A15: 13 | B15: Dự án thành phần DATP 1-3: Bồi thường, hỗ trợ, tái định cư và xây dựng đường gom, đường bên trên địa phận thành phố Hồ Chí Minh (đoạn sông Sài Gòn đến kênh Thầy Cai) thuộc Dự án đầu tư xây dựng Đường vành đai 4 thành phố Hồ Chí Minh | D15: BQL DA ĐTXD các công trình giao thông thành phố (trước đây là Ban Quản lý dự án đầu tư xây dựng các công trình giao thông ) | E15: Dự án | F15: Khu vực Thành phố Hồ Chí Minh cũ
A16: 14 | B16: Dự án thành phần DATP 1-5: Bồi thường, hỗ trợ, tái định cư và xây dựng đường gom, đường bên trên địa phận thành phố Hồ Chí Minh (đoạn từ ranh giới tỉnh Tây Ninh đến cảng Hiệp Phước, Hồ Chí Minh) thuộc Dự án đầu tư xây dựng Đường vành đai 4 thành phố Hồ Chí Minh | D16: BQL DA ĐTXD các công trình giao thông thành phố (trước đây là Ban Quản lý dự án đầu tư xây dựng các công trình giao thông ) | E16: Dự án | F16: Khu vực Thành phố Hồ Chí Minh cũ
A17: 15 | B17: Dự án thành phần 1: bồi thường, hỗ trợ và tái định cư Dự án xây dựng cầu Thủ Thiêm 4 | D17: BQL DA ĐTXD các công trình giao thông thành phố (trước đây là Ban Quản lý dự án đầu tư xây dựng các công trình giao thông ) | E17: Dự án | F17: Khu vực Thành phố Hồ Chí Minh cũ
A18: 16 | B18: Dự án thành phần 1- Bồi thường, hỗ trợ và tái định cư dự án xây dựng cầu Cần Giờ thuộc dự án Đầu tư xây dựng cầu Cần Giờ theo phương thức đối tác công tư (PPP) | D18: BQL DA ĐTXD các công trình giao thông thành phố (trước đây là Ban Quản lý dự án đầu tư xây dựng các công trình giao thông ) | E18: Dự án | F18: Khu vực Thành phố Hồ Chí Minh cũ
... A22: 20 | B22: Dự án Nâng cấp đường Lương Định Của (đoạn từ Trần Não đến Nguyễn Thị Định) | D22: BQL DA ĐTXD các công trình giao thông thành phố (trước đây là Ban Quản lý dự án đầu tư xây dựng các công trình giao thông ) | E22: Dự án | F22: Khu vực Thành phố Hồ Chí Minh cũ
B23: Dự án Khu đô thị mới Thủ Thiêm | D23: Phòng Bồi thường, hỗ trợ, tái định cư Sở | E23: Dự án trọng điểm | F23: Khu vực Thành phố Hồ Chí Minh cũ; Không thấy trong danh dách 148 dự án
B24: Dự án xây dựng tuyến kết nối từ đường Phạm Văn Đồng đến nút giao thông Gò Dưa – Quốc lộ 1 (Vành đai 2 đoạn 3) trên địa bàn phường Hiệp Bình và phường Tam Bình | D24: Phòng Bồi thường, hỗ trợ, tái định cư Sở | E24: Dự án trọng điểm | F24: Khu vực Thành phố Hồ Chí Minh cũ; Không thấy trong danh dách 148 dự án
B25: Dự án Đầu tư xây dựng Đại học Quốc gia Thành phố | C25: Tiến độ thực hiện công tác bồi thường, hỗ trợ, tái định cư trên địa bàn phường Linh Xuân | D25: Phòng Bồi thường, hỗ trợ, tái định cư Sở | E25: Dự án trọng điểm | F25: Khu vực Thành phố Hồ Chí Minh cũ; Không thấy trong danh dách 148 dự án
B26: Dự án Đầu tư xây dựng Đại học Quốc gia Thành phố | C26: Tiến độ thực hiện công tác Bồi thường, hỗ trợ, tái định cư trên địa bàn phường Đông Hòa | D26: Phòng Bồi thường, hỗ trợ, tái định cư Sở | E26: Dự án trọng điểm | F26: Khu vực Thành phố Hồ Chí Minh cũ; Không thấy trong danh dách 148 dự án
B27: Dự án Đầu tư xây dựng Đại học Quốc gia Thành phố | C27: Dự án tái định cư Đại học Quốc Gia: | D27: Phòng Bồi thường, hỗ trợ, tái định cư Sở | E27: Dự án trọng điểm | F27: Khu vực Thành phố Hồ Chí Minh cũ; Không thấy trong danh dách 148 dự án
B28: Dự án Khu liên hợp Thể dục thể thao Quốc gia Rạch Chiếc | D28: Phòng Bồi thường, hỗ trợ, tái định cư Sở | E28: Dự án trọng điểm | F28: Khu vực Thành phố Hồ Chí Minh cũ; Không thấy trong danh dách 148 dự án
B29: Dự án đường sắt tốc độ cao trên trục Bắc – Nam | D29: Phòng Bồi thường, hỗ trợ, tái định cư Sở | E29: Dự án trọng điểm | F29: Khu vực Thành phố Hồ Chí Minh cũ; Không thấy trong danh dách 148 dự án
B30: Dự án Chỉnh trang đô thị khu Mả Lạng và Chợ Gà - Gạo trên địa bàn phường Cầu Ông Lãnh và phường Bến Thành | C30: Đối với khu Mả Lạng trên địa bàn phường Cầu Ông Lãnh | D30: Phòng Bồi thường, hỗ trợ, tái định cư Sở | E30: Dự án trọng điểm | F30: Khu vực Thành phố Hồ Chí Minh cũ; Không thấy trong danh dách 148 dự án
B31: Dự án Chỉnh trang đô thị khu Mả Lạng và Chợ Gà - Gạo trên địa bàn phường Cầu Ông Lãnh và phường Bến Thành | C31: Đối với khu Chợ Gà - Gạo trên địa bàn phường Bến Thành | D31: Phòng Bồi thường, hỗ trợ, tái định cư Sở | E31: Dự án trọng điểm | F31: Khu vực Thành phố Hồ Chí Minh cũ; Không thấy trong danh dách 148 dự án
A32: 21 | B32: Dự án Bồi thường, giải phóng mặt bằng và tái định cư Khu Công nghệ cao Thành phố Hồ Chí Minh trên địa bàn Quận 9 | D32: Ban Quản lý khu công nghệ cao | E32: Dự án trọng điểm | F32: Khu vực Thành phố Hồ Chí Minh cũ
A33: 22 | B33: Bồi thường giải phóng mặt bằng Công viên Lịch sử văn hóa dân tộc (theo QĐ duyệt dự án số 2227/QĐ - TC-BVG ngày 04/3/2008 của Sở Tài Chính ) | D33: Ban Quản lý Công viên lịch sử Văn hóa-Dân tộc TPHCM | E33: Dự án | F33: Khu vực Thành phố Hồ Chí Minh cũ
A34: 23 | B34: Dự án đầu tư xây dựng tuyến tàu điện ngầm số 2 Thành phố Hồ Chí Minh, tuyến Bến Thành - Tham Lương | D34: Ban Quản lý Đường sắt đô thị | E34: Dự án | F34: Khu vực Thành phố Hồ Chí Minh cũ
A35: 24 | B35: Bồi thường, hỗ trợ, tái định cư phục vụ dự án Tuyến đường sắt Bến Thành - Cần Giờ | D35: Ban Quản lý Đường sắt đô thị | E35: Dự án trọng điểm | F35: Khu vực Thành phố Hồ Chí Minh cũ
A36: 25 | B36: Bồi thường, hỗ trợ, tái định cư phục vụ Dự án tuyến đường sắt đô thị số 2, đoạn Bến Thành - Thủ Thiêm | D36: Ban Quản lý Đường sắt đô thị | E36: Dự án | F36: Khu vực Thành phố Hồ Chí Minh cũ
A37: 26 | B37: Dự án Đầu tư mở rộng đường Trần Bình Trọng, phường Vườn Lài (bao gồm các giao lộ trên tuyển) | D37: Ban QLDA ĐTXD phường Vườn Lài | E37: Dự án | F37: Khu vực Thành phố Hồ Chí Minh cũ
A38: 27 | B38: Xây dựng Trường Mầm non Phường 04 | D38: Ban QLDA ĐTXD phường Bình Thới | E38: Dự án | F38: Khu vực Thành phố Hồ Chí Minh cũ
A39: 28 | B39: Xây dựng hạ tầng và đường giao thông khu trường đua Phú Thọ | D39: Ban QLDA ĐTXD phường Bình Thới | E39: Dự án | F39: Khu vực Thành phố Hồ Chí Minh cũ
A40: 29 | B40: Xây dựng mới Trường Mầm non Phường 7 | D40: Ban QLDA ĐTXD phường Bình Thới | E40: Dự án | F40: Khu vực Thành phố Hồ Chí Minh cũ
A41: 30 | B41: Xây dựng Trường THPT Đông Hưng Thuận tại khu đất 5,8ha Đài phát sóng Quán Tre | D41: Ban QLDA ĐTXD phường Đông Hưng Thuận | E41: Dự án | F41: Khu vực Thành phố Hồ Chí Minh cũ
A42: 31 | B42: Mở rộng đường D3 phường 10 quận Gò Vấp (đoạn từ Phan Văn Trị đến đường Quang Trung) | D42: Ban QLDA phường Hạnh Thông | E42: Dự án | F42: Khu vực Thành phố Hồ Chí Minh cũ
A43: 32 | B43: Xây dựng Trường MN Vĩnh Lộc A, xã Vĩnh Lộc A | D43: Ban QLDA xã Vĩnh Lộc | E43: Dự án | F43: Khu vực Thành phố Hồ Chí Minh cũ
...
